  0%|          | 0/11 [00:00<?, ?it/s]100%|██████████| 11/11 [00:00<00:00, 394.28it/s]
Traceback (most recent call last):
  File "/rds/general/user/mo2016/home/anaconda3/envs/env1/lib/python3.8/site-packages/pandas/core/indexes/base.py", line 3621, in get_loc
    return self._engine.get_loc(casted_key)
  File "pandas/_libs/index.pyx", line 136, in pandas._libs.index.IndexEngine.get_loc
  File "pandas/_libs/index.pyx", line 163, in pandas._libs.index.IndexEngine.get_loc
  File "pandas/_libs/hashtable_class_helper.pxi", line 5198, in pandas._libs.hashtable.PyObjectHashTable.get_item
  File "pandas/_libs/hashtable_class_helper.pxi", line 5206, in pandas._libs.hashtable.PyObjectHashTable.get_item
KeyError: 'model_param_id'

The above exception was the direct cause of the following exception:

Traceback (most recent call last):
  File "/rds/general/user/mo2016/home/anaconda3/envs/env1/lib/python3.8/site-packages/pandas/core/frame.py", line 3799, in _set_item_mgr
    loc = self._info_axis.get_loc(key)
  File "/rds/general/user/mo2016/home/anaconda3/envs/env1/lib/python3.8/site-packages/pandas/core/indexes/base.py", line 3623, in get_loc
    raise KeyError(key) from err
KeyError: 'model_param_id'

During handling of the above exception, another exception occurred:

Traceback (most recent call last):
  File "database_scripts/insert_analytical_output_instabilities.py", line 52, in <module>
    analyticalOutput_df_to_sql(lsa_df_instabilities, circuit_n, variant, n_samples)
  File "/rds/general/user/mo2016/home/Documents/modelling/lib/database/databaseFunctions.py", line 107, in analyticalOutput_df_to_sql
    lsa_df['model_param_id'] = lsa_df.apply(lambda row: f"{row['parID']}_circuit:{row['circuit_n']}_variant:{row['variant']}_samples:{row['n_samples']}", axis=1)
  File "/rds/general/user/mo2016/home/anaconda3/envs/env1/lib/python3.8/site-packages/pandas/core/frame.py", line 3645, in __setitem__
    self._set_item_frame_value(key, value)
  File "/rds/general/user/mo2016/home/anaconda3/envs/env1/lib/python3.8/site-packages/pandas/core/frame.py", line 3788, in _set_item_frame_value
    self._set_item_mgr(key, arraylike)
  File "/rds/general/user/mo2016/home/anaconda3/envs/env1/lib/python3.8/site-packages/pandas/core/frame.py", line 3802, in _set_item_mgr
    self._mgr.insert(len(self._info_axis), key, value)
  File "/rds/general/user/mo2016/home/anaconda3/envs/env1/lib/python3.8/site-packages/pandas/core/internals/managers.py", line 1235, in insert
    raise ValueError(
ValueError: Expected a 1D array, got an array with shape (0, 25)
  0%|          | 0/11 [00:00<?, ?it/s]100%|██████████| 11/11 [00:00<00:00, 425.62it/s]
Traceback (most recent call last):
  File "/rds/general/user/mo2016/home/anaconda3/envs/env1/lib/python3.8/site-packages/pandas/core/indexes/base.py", line 3621, in get_loc
    return self._engine.get_loc(casted_key)
  File "pandas/_libs/index.pyx", line 136, in pandas._libs.index.IndexEngine.get_loc
  File "pandas/_libs/index.pyx", line 163, in pandas._libs.index.IndexEngine.get_loc
  File "pandas/_libs/hashtable_class_helper.pxi", line 5198, in pandas._libs.hashtable.PyObjectHashTable.get_item
  File "pandas/_libs/hashtable_class_helper.pxi", line 5206, in pandas._libs.hashtable.PyObjectHashTable.get_item
KeyError: 'model_param_id'

The above exception was the direct cause of the following exception:

Traceback (most recent call last):
  File "/rds/general/user/mo2016/home/anaconda3/envs/env1/lib/python3.8/site-packages/pandas/core/frame.py", line 3799, in _set_item_mgr
    loc = self._info_axis.get_loc(key)
  File "/rds/general/user/mo2016/home/anaconda3/envs/env1/lib/python3.8/site-packages/pandas/core/indexes/base.py", line 3623, in get_loc
    raise KeyError(key) from err
KeyError: 'model_param_id'

During handling of the above exception, another exception occurred:

Traceback (most recent call last):
  File "database_scripts/insert_analytical_output_instabilities.py", line 52, in <module>
    analyticalOutput_df_to_sql(lsa_df_instabilities, circuit_n, variant, n_samples)
  File "/rds/general/user/mo2016/home/Documents/modelling/lib/database/databaseFunctions.py", line 107, in analyticalOutput_df_to_sql
    lsa_df['model_param_id'] = lsa_df.apply(lambda row: f"{row['parID']}_circuit:{row['circuit_n']}_variant:{row['variant']}_samples:{row['n_samples']}", axis=1)
  File "/rds/general/user/mo2016/home/anaconda3/envs/env1/lib/python3.8/site-packages/pandas/core/frame.py", line 3645, in __setitem__
    self._set_item_frame_value(key, value)
  File "/rds/general/user/mo2016/home/anaconda3/envs/env1/lib/python3.8/site-packages/pandas/core/frame.py", line 3788, in _set_item_frame_value
    self._set_item_mgr(key, arraylike)
  File "/rds/general/user/mo2016/home/anaconda3/envs/env1/lib/python3.8/site-packages/pandas/core/frame.py", line 3802, in _set_item_mgr
    self._mgr.insert(len(self._info_axis), key, value)
  File "/rds/general/user/mo2016/home/anaconda3/envs/env1/lib/python3.8/site-packages/pandas/core/internals/managers.py", line 1235, in insert
    raise ValueError(
ValueError: Expected a 1D array, got an array with shape (0, 25)
  0%|          | 0/11 [00:00<?, ?it/s]100%|██████████| 11/11 [00:00<00:00, 410.69it/s]
Traceback (most recent call last):
  File "/rds/general/user/mo2016/home/anaconda3/envs/env1/lib/python3.8/site-packages/pandas/core/indexes/base.py", line 3621, in get_loc
    return self._engine.get_loc(casted_key)
  File "pandas/_libs/index.pyx", line 136, in pandas._libs.index.IndexEngine.get_loc
  File "pandas/_libs/index.pyx", line 163, in pandas._libs.index.IndexEngine.get_loc
  File "pandas/_libs/hashtable_class_helper.pxi", line 5198, in pandas._libs.hashtable.PyObjectHashTable.get_item
  File "pandas/_libs/hashtable_class_helper.pxi", line 5206, in pandas._libs.hashtable.PyObjectHashTable.get_item
KeyError: 'model_param_id'

The above exception was the direct cause of the following exception:

Traceback (most recent call last):
  File "/rds/general/user/mo2016/home/anaconda3/envs/env1/lib/python3.8/site-packages/pandas/core/frame.py", line 3799, in _set_item_mgr
    loc = self._info_axis.get_loc(key)
  File "/rds/general/user/mo2016/home/anaconda3/envs/env1/lib/python3.8/site-packages/pandas/core/indexes/base.py", line 3623, in get_loc
    raise KeyError(key) from err
KeyError: 'model_param_id'

During handling of the above exception, another exception occurred:

Traceback (most recent call last):
  File "database_scripts/insert_analytical_output_instabilities.py", line 52, in <module>
    analyticalOutput_df_to_sql(lsa_df_instabilities, circuit_n, variant, n_samples)
  File "/rds/general/user/mo2016/home/Documents/modelling/lib/database/databaseFunctions.py", line 107, in analyticalOutput_df_to_sql
    lsa_df['model_param_id'] = lsa_df.apply(lambda row: f"{row['parID']}_circuit:{row['circuit_n']}_variant:{row['variant']}_samples:{row['n_samples']}", axis=1)
  File "/rds/general/user/mo2016/home/anaconda3/envs/env1/lib/python3.8/site-packages/pandas/core/frame.py", line 3645, in __setitem__
    self._set_item_frame_value(key, value)
  File "/rds/general/user/mo2016/home/anaconda3/envs/env1/lib/python3.8/site-packages/pandas/core/frame.py", line 3788, in _set_item_frame_value
    self._set_item_mgr(key, arraylike)
  File "/rds/general/user/mo2016/home/anaconda3/envs/env1/lib/python3.8/site-packages/pandas/core/frame.py", line 3802, in _set_item_mgr
    self._mgr.insert(len(self._info_axis), key, value)
  File "/rds/general/user/mo2016/home/anaconda3/envs/env1/lib/python3.8/site-packages/pandas/core/internals/managers.py", line 1235, in insert
    raise ValueError(
ValueError: Expected a 1D array, got an array with shape (0, 25)
  0%|          | 0/11 [00:00<?, ?it/s]100%|██████████| 11/11 [00:00<00:00, 429.58it/s]
Traceback (most recent call last):
  File "/rds/general/user/mo2016/home/anaconda3/envs/env1/lib/python3.8/site-packages/pandas/core/indexes/base.py", line 3621, in get_loc
    return self._engine.get_loc(casted_key)
  File "pandas/_libs/index.pyx", line 136, in pandas._libs.index.IndexEngine.get_loc
  File "pandas/_libs/index.pyx", line 163, in pandas._libs.index.IndexEngine.get_loc
  File "pandas/_libs/hashtable_class_helper.pxi", line 5198, in pandas._libs.hashtable.PyObjectHashTable.get_item
  File "pandas/_libs/hashtable_class_helper.pxi", line 5206, in pandas._libs.hashtable.PyObjectHashTable.get_item
KeyError: 'model_param_id'

The above exception was the direct cause of the following exception:

Traceback (most recent call last):
  File "/rds/general/user/mo2016/home/anaconda3/envs/env1/lib/python3.8/site-packages/pandas/core/frame.py", line 3799, in _set_item_mgr
    loc = self._info_axis.get_loc(key)
  File "/rds/general/user/mo2016/home/anaconda3/envs/env1/lib/python3.8/site-packages/pandas/core/indexes/base.py", line 3623, in get_loc
    raise KeyError(key) from err
KeyError: 'model_param_id'

During handling of the above exception, another exception occurred:

Traceback (most recent call last):
  File "database_scripts/insert_analytical_output_instabilities.py", line 52, in <module>
    analyticalOutput_df_to_sql(lsa_df_instabilities, circuit_n, variant, n_samples)
  File "/rds/general/user/mo2016/home/Documents/modelling/lib/database/databaseFunctions.py", line 107, in analyticalOutput_df_to_sql
    lsa_df['model_param_id'] = lsa_df.apply(lambda row: f"{row['parID']}_circuit:{row['circuit_n']}_variant:{row['variant']}_samples:{row['n_samples']}", axis=1)
  File "/rds/general/user/mo2016/home/anaconda3/envs/env1/lib/python3.8/site-packages/pandas/core/frame.py", line 3645, in __setitem__
    self._set_item_frame_value(key, value)
  File "/rds/general/user/mo2016/home/anaconda3/envs/env1/lib/python3.8/site-packages/pandas/core/frame.py", line 3788, in _set_item_frame_value
    self._set_item_mgr(key, arraylike)
  File "/rds/general/user/mo2016/home/anaconda3/envs/env1/lib/python3.8/site-packages/pandas/core/frame.py", line 3802, in _set_item_mgr
    self._mgr.insert(len(self._info_axis), key, value)
  File "/rds/general/user/mo2016/home/anaconda3/envs/env1/lib/python3.8/site-packages/pandas/core/internals/managers.py", line 1235, in insert
    raise ValueError(
ValueError: Expected a 1D array, got an array with shape (0, 25)
  0%|          | 0/11 [00:00<?, ?it/s]100%|██████████| 11/11 [00:00<00:00, 390.71it/s]
=>> PBS: job killed: walltime 625 exceeded limit 600
